#VRML_SIM R2023b utf8

EXTERNPROTO "https://raw.githubusercontent.com/cyberbotics/webots/R2023b/projects/objects/backgrounds/protos/TexturedBackground.proto"
EXTERNPROTO "https://raw.githubusercontent.com/cyberbotics/webots/R2023b/projects/objects/backgrounds/protos/TexturedBackgroundLight.proto"
EXTERNPROTO "https://raw.githubusercontent.com/cyberbotics/webots/R2023b/projects/objects/floors/protos/Floor.proto"

WorldInfo {
  basicTimeStep 10
  contactProperties [
    ContactProperties {
      coulombFriction [
        3
      ]
      bounce 0
    }
  ]
}
Viewpoint {
  orientation 0.17486329758963143 0.07836588934359474 -0.9814691103358616 2.4204075842501878
  position 0.9297208095672017 0.8099367602274687 0.43269149167455856
}
TexturedBackground {
}
TexturedBackgroundLight {
}
DEF MOSAC Robot {
  translation 0 0 0.139
  children [
    Gyro {
      translation 0 -0.005 0.036
      rotation 0 0 1 3.14159
    }
    Accelerometer {
      translation 0 -0.005 0.036
      rotation 0 0 1 3.14159
    }
    Shape {
      appearance DEF chasis_base_link_material PBRAppearance {
        baseColor 0.298039 0.298039 0.298039
        roughness 1
        metalness 0
      }
      geometry DEF chasis_base_link Mesh {
        url [
          "../protos/URDF_MOSAC_V3/meshes/chasis_base_link.STL"
        ]
      }
    }
    HingeJoint {
      jointParameters HingeJointParameters {
        anchor 0.095 -0.05275 0.0032
        dampingConstant 0.673885
      }
      device [
        RotationalMotor {
          name "BFR_joint"
        }
        PositionSensor {
          name "BFR_joint_sensor"
        }
      ]
      endPoint Solid {
        translation 0.095 -0.05275 0.0032
        rotation 0.5773502691896257 -0.5773502691896256 -0.5773502691896258 2.094395
        children [
          Shape {
            appearance DEF BFR_link_material PBRAppearance {
              baseColor 0.792157 0.819608 0.933333
              roughness 1
              metalness 0
            }
            geometry DEF BFR_link Mesh {
              url [
                "../protos/URDF_MOSAC_V3/meshes/BFR_link.STL"
              ]
            }
          }
          HingeJoint {
            jointParameters HingeJointParameters {
              anchor 0.02675 0.010265 -0.02005
              dampingConstant 0.673885
            }
            device [
              RotationalMotor {
                name "FR_servo_femur_joint"
              }
              PositionSensor {
                name "FR_servo_femur_joint_sensor"
              }
            ]
            endPoint Solid {
              translation 0.02675 0.010265 -0.02005
              rotation -7.486770510940091e-23 1 -7.486770510940091e-23 1.5708
              children [
                Shape {
                  appearance DEF FR_servo_femur_link_material PBRAppearance {
                    roughness 1
                    metalness 0
                  }
                  geometry DEF FR_servo_femur_link Mesh {
                    url [
                      "../protos/URDF_MOSAC_V3/meshes/FR_servo_femur_link.STL"
                    ]
                  }
                }
                HingeJoint {
                  jointParameters HingeJointParameters {
                    axis 0 0 -1
                    anchor -0.07355 -0.067752 0.02225
                  }
                  device [
                    PositionSensor {
                      name "FR_tibia_joint_sensor"
                    }
                  ]
                  endPoint Solid {
                    translation -0.07355 -0.067752 0.02225
                    rotation 0 0 -1 0
                    children [
                      DEF PFR Solid {
                        translation 0.074 -0.085 0
                        name "PFR"
                      }
                      TouchSensor {
                        name "touch_FR"
                        boundingObject DEF Paw_FR Pose {
                          translation 0.074246 -0.068 0
                          children [
                            Cylinder {
                              height 0.016
                              radius 0.01725
                            }
                          ]
                        }
                      }
                      Shape {
                        appearance DEF FR_tibia_link_material PBRAppearance {
                          roughness 1
                          metalness 0
                        }
                        geometry DEF FR_tibia_link Mesh {
                          url [
                            "../protos/URDF_MOSAC_V3/meshes/FR_tibia_link.STL"
                          ]
                        }
                      }
                      HingeJoint {
                        jointParameters HingeJointParameters {
                          axis 0 0 -1
                          anchor -0.019092 0.019092 -0.00425
                        }
                        device [
                          PositionSensor {
                            name "FR_rotula_grande_tibia_joint_sensor"
                          }
                        ]
                        endPoint Solid {
                          translation -0.019092 0.019092 -0.00425
                          rotation 0 0 -1 0
                          children [
                            Shape {
                              appearance DEF FR_rotula_grande_tibia_link_material PBRAppearance {
                                baseColor 0.79216 0.60392 0.22745
                                roughness 1
                                metalness 0
                              }
                              geometry DEF FR_rotula_grande_tibia_link Mesh {
                                url [
                                  "../protos/URDF_MOSAC_V3/meshes/FR_rotula_grande_tibia_link.STL"
                                ]
                              }
                            }
                            HingeJoint {
                              jointParameters HingeJointParameters {
                                axis 0 0 -1
                                anchor 0.07355 0.067752 0
                              }
                              device [
                                PositionSensor {
                                  name "FR_rotula_grande_shoulder_joint_sensor"
                                }
                              ]
                              endPoint SolidReference {
                                solidName "FR_shoulder_link"
                              }
                            }
                          ]
                          name "FR_rotula_grande_tibia_link"
                          physics Physics {
                            density -1
                            mass 0.0250314
                            centerOfMass [
                              0.0367752 0.033876 0
                            ]
                            inertiaMatrix [
                              1.983e-05 2.329e-05 4.294e-05
                              2.101e-05 0 0
                            ]
                          }
                        }
                      }
                    ]
                    name "FR_tibia_link"
                    boundingObject USE Paw_FR
                    physics Physics {
                      density -1
                      mass 0.0286325
                      centerOfMass [
                        0.0330659 -0.0331963 -0.0009959
                      ]
                      inertiaMatrix [
                        3.543e-05 4.151e-05 7.515e-05
                        -3.636e-05 1.44e-06 -1.45e-06
                      ]
                    }
                  }
                }
              ]
              name "FR_servo_femur_link"
              physics Physics {
                density -1
                mass 0.0324891
                centerOfMass [
                  -0.0261151 -0.0240545 0.0170025
                ]
                inertiaMatrix [
                  2.775e-05 3.21e-05 5.522e-05
                  2.645e-05 -4.41e-06 -4.06e-06
                ]
              }
            }
          }
          HingeJoint {
            jointParameters HingeJointParameters {
              anchor 0.02375 -0.010265 -0.04005
              dampingConstant 0.673885
            }
            device [
              RotationalMotor {
                name "FR_servo_tibia_joint"
              }
              PositionSensor {
                name "FR_servo_tibia_joint_sensor"
              }
            ]
            endPoint Solid {
              translation 0.02375 -0.010265 -0.04005
              rotation -2.2460356453413094e-22 1 -7.486785484471032e-23 1.5707959999999994
              children [
                Shape {
                  appearance DEF FR_servo_tibia_link_material PBRAppearance {
                    baseColor 0.898039 0.917647 0.929412
                    roughness 1
                    metalness 0
                  }
                  geometry DEF FR_servo_tibia_link Mesh {
                    url [
                      "../protos/URDF_MOSAC_V3/meshes/FR_servo_tibia_link.STL"
                    ]
                  }
                }
                HingeJoint {
                  jointParameters HingeJointParameters {
                    axis 0 0 -1
                    anchor 0.022981 0.006918 0.0175
                  }
                  device [
                    PositionSensor {
                      name "FR_rotula_chica_servo_joint_sensor"
                    }
                  ]
                  endPoint Solid {
                    translation 0.022981 0.006918 0.0175
                    rotation 0 0 -1 0
                    children [
                      Shape {
                        appearance DEF FR_rotula_chica_servo_link_material PBRAppearance {
                          baseColor 0.792157 0.603922 0.227451
                          roughness 1
                          metalness 0
                        }
                        geometry DEF FR_rotula_chica_servo_link Mesh {
                          url [
                            "../protos/URDF_MOSAC_V3/meshes/FR_rotula_chica_servo_link.STL"
                          ]
                        }
                      }
                      HingeJoint {
                        jointParameters HingeJointParameters {
                          axis 0 0 -1
                          anchor -0.023889 0.032704 0
                        }
                        device [
                          PositionSensor {
                            name "FR_rotula_chica_shoulder_joint_sensor"
                          }
                        ]
                        endPoint SolidReference {
                          solidName "FR_shoulder_link"
                        }
                      }
                    ]
                    name "FR_rotula_chica_servo_link"
                    physics Physics {
                      density -1
                      mass 0.0212414
                      centerOfMass [
                        -0.0119447 0.016352 0
                      ]
                      inertiaMatrix [
                        4.16e-06 2.42e-06 6.45e-06
                        -2.72e-06 0 0
                      ]
                    }
                  }
                }
              ]
              name "FR_servo_tibia_link"
              physics Physics {
                density -1
                mass 0.00954161
                centerOfMass [
                  0.0159835 0.00481577 0.0107582
                ]
                inertiaMatrix [
                  6.3e-07 1.46e-06 1.15e-06
                  2.8e-07 4.7e-07 1.4e-07
                ]
              }
            }
          }
          HingeJoint {
            jointParameters HingeJointParameters {
              axis -1 0 0
              anchor 0.02675 0.010265 -0.02005
            }
            device [
              PositionSensor {
                name "FR_shoulder_joint_sensor"
              }
            ]
            endPoint Solid {
              translation 0.02675 0.010265 -0.02005
              rotation -1.533293667219667e-19 1 -3.066587334439334e-19 1.570796
              children [
                Shape {
                  appearance DEF FR_shoulder_link_material PBRAppearance {
                    baseColor 0.752941 0 0
                    roughness 1
                    metalness 0
                  }
                  geometry DEF FR_shoulder_link Mesh {
                    url [
                      "../protos/URDF_MOSAC_V3/meshes/FR_shoulder_link.STL"
                    ]
                  }
                }
              ]
              name "FR_shoulder_link"
              physics Physics {
                density -1
                mass 0.0142291
                centerOfMass [
                  -0.00027422 0.0161256 0.0133504
                ]
                inertiaMatrix [
                  1.41e-06 4.67e-06 5.4e-06
                  -1e-08 -3.1e-07 2e-07
                ]
              }
            }
          }
        ]
        name "BFR_link"
        physics Physics {
          density -1
          mass 0.146948
          centerOfMass [
            0.00580356 -2.21e-06 -0.0309194
          ]
          inertiaMatrix [
            5.469e-05 4.872e-05 3.354e-05
            0 7.5e-07 6.7e-07
          ]
        }
      }
    }
    HingeJoint {
      jointParameters HingeJointParameters {
        anchor -0.095 -0.05275 0.0032
        dampingConstant 0.673885
      }
      device [
        RotationalMotor {
          name "BBR_joint"
        }
        PositionSensor {
          name "BBR_joint_sensor"
        }
      ]
      endPoint Solid {
        translation -0.095 -0.05275 0.0032
        rotation 0.5773502691896257 -0.5773502691896257 -0.5773502691896257 2.094395
        children [
          Shape {
            appearance DEF BBR_link_material PBRAppearance {
              baseColor 0.792157 0.819608 0.933333
              roughness 1
              metalness 0
            }
            geometry DEF BBR_link Mesh {
              url [
                "../protos/URDF_MOSAC_V3/meshes/BBR_link.STL"
              ]
            }
          }
          HingeJoint {
            jointParameters HingeJointParameters {
              anchor 0.02675 0.010265 0.04005
              dampingConstant 0.673885
            }
            device [
              RotationalMotor {
                name "BR_servo_femur_joint"
              }
              PositionSensor {
                name "BR_servo_femur_joint_sensor"
              }
            ]
            endPoint Solid {
              translation 0.02675 0.010265 0.04005
              rotation -2.3396204638971974e-24 1 -2.3396204638971974e-24 1.570796
              children [
                Shape {
                  appearance DEF BR_servo_femur_link_material PBRAppearance {
                    baseColor 0.298039 0.298039 0.298039
                    roughness 1
                    metalness 0
                  }
                  geometry DEF BR_servo_femur_link Mesh {
                    url [
                      "../protos/URDF_MOSAC_V3/meshes/BR_servo_femur_link.STL"
                    ]
                  }
                }
                HingeJoint {
                  jointParameters HingeJointParameters {
                    axis 0 0 -1
                    anchor -0.07355 -0.067752 0.02225
                  }
                  device [
                    PositionSensor {
                      name "BR_tibia_joint_sensor"
                    }
                  ]
                  endPoint Solid {
                    translation -0.07355 -0.067752 0.02225
                    rotation 0 0 -1 0
                    children [
                      DEF PBR Solid {
                        translation 0.074 -0.085 0
                      }
                      TouchSensor {
                        name "touch_BR"
                        boundingObject DEF Paw_BR Pose {
                          translation 0.074246 -0.068 0
                          children [
                            Cylinder {
                              height 0.016
                              radius 0.01725
                            }
                          ]
                        }
                      }
                      Shape {
                        appearance DEF BR_tibia_link_material PBRAppearance {
                          roughness 1
                          metalness 0
                        }
                        geometry DEF BR_tibia_link Mesh {
                          url [
                            "../protos/URDF_MOSAC_V3/meshes/BR_tibia_link.STL"
                          ]
                        }
                      }
                      HingeJoint {
                        jointParameters HingeJointParameters {
                          axis 0 0 1
                          anchor -0.019092 0.019092 -0.00425
                        }
                        device [
                          PositionSensor {
                            name "BR_rotula_grande_tibia_joint_sensor"
                          }
                        ]
                        endPoint Solid {
                          translation -0.019092 0.019092 -0.00425
                          children [
                            Shape {
                              appearance DEF BR_rotula_grande_tibia_link_material PBRAppearance {
                                baseColor 0.776471 0.756863 0.737255
                                roughness 1
                                metalness 0
                              }
                              geometry DEF BR_rotula_grande_tibia_link Mesh {
                                url [
                                  "../protos/URDF_MOSAC_V3/meshes/BR_rotula_grande_tibia_link.STL"
                                ]
                              }
                            }
                            HingeJoint {
                              jointParameters HingeJointParameters {
                                axis 0 0 1
                                anchor 0.07355 0.067752 0
                              }
                              device [
                                PositionSensor {
                                  name "BR_rotula_grande_shoulder_joint_sensor"
                                }
                              ]
                              endPoint SolidReference {
                                solidName "BR_shoulder_link"
                              }
                            }
                          ]
                          name "BR_rotula_grande_tibia_link"
                          physics Physics {
                            density -1
                            mass 0.0250314
                            centerOfMass [
                              0.0373058 0.0332908 0
                            ]
                            inertiaMatrix [
                              1.917e-05 2.395e-05 4.294e-05
                              2.094e-05 0 0
                            ]
                          }
                        }
                      }
                    ]
                    name "BR_tibia_link"
                    boundingObject USE Paw_BR
                    physics Physics {
                      density -1
                      mass 0.0286325
                      centerOfMass [
                        0.0325373 -0.0337146 -0.0009959
                      ]
                      inertiaMatrix [
                        3.658e-05 4.036e-05 7.515e-05
                        -3.644e-05 1.42e-06 -1.47e-06
                      ]
                    }
                  }
                }
              ]
              name "BR_servo_femur_link"
              physics Physics {
                density -1
                mass 0.0324891
                centerOfMass [
                  -0.0264919 -0.023639 0.0170025
                ]
                inertiaMatrix [
                  2.692e-05 3.294e-05 5.522e-05
                  2.637e-05 -4.47e-06 -3.99e-06
                ]
              }
            }
          }
          HingeJoint {
            jointParameters HingeJointParameters {
              anchor 0.02375 -0.010265 0.02005
              dampingConstant 0.673885
            }
            device [
              RotationalMotor {
                name "BR_servo_tibia_joint"
              }
              PositionSensor {
                name "BR_servo_tibia_joint_sensor"
              }
            ]
            endPoint Solid {
              translation 0.02375 -0.010265 0.02005
              rotation 5.849051159742993e-25 1 0 1.570796
              children [
                Shape {
                  appearance DEF BR_servo_tibia_link_material PBRAppearance {
                    baseColor 0.898039 0.917647 0.929412
                    roughness 1
                    metalness 0
                  }
                  geometry DEF BR_servo_tibia_link Mesh {
                    url [
                      "../protos/URDF_MOSAC_V3/meshes/BR_servo_tibia_link.STL"
                    ]
                  }
                }
                HingeJoint {
                  jointParameters HingeJointParameters {
                    axis 0 0 -1
                    anchor 0.022981 0.006918 0.0175
                  }
                  device [
                    PositionSensor {
                      name "BR_rotula_chica_servo_joint_sensor"
                    }
                  ]
                  endPoint Solid {
                    translation 0.022981 0.006918 0.0175
                    rotation 0 0 -1 0
                    children [
                      Shape {
                        appearance DEF BR_rotula_chica_servo_link_material PBRAppearance {
                          baseColor 0.792157 0.603922 0.227451
                          roughness 1
                          metalness 0
                        }
                        geometry DEF BR_rotula_chica_servo_link Mesh {
                          url [
                            "../protos/URDF_MOSAC_V3/meshes/BR_rotula_chica_servo_link.STL"
                          ]
                        }
                      }
                      HingeJoint {
                        jointParameters HingeJointParameters {
                          axis 0 0 -1
                          anchor -0.023889 0.032704 0
                        }
                        device [
                          PositionSensor {
                            name "BR_rotula_chica_shoulder_joint_sensor"
                          }
                        ]
                        endPoint SolidReference {
                          solidName "BR_shoulder_link"
                        }
                      }
                    ]
                    name "BR_rotula_chica_servo_link"
                    physics Physics {
                      density -1
                      mass 0.0212414
                      centerOfMass [
                        -0.0116849 0.0165386 0
                      ]
                      inertiaMatrix [
                        4.24e-06 2.33e-06 6.45e-06
                        -2.7e-06 0 0
                      ]
                    }
                  }
                }
              ]
              name "BR_servo_tibia_link"
              physics Physics {
                density -1
                mass 0.00954161
                centerOfMass [
                  0.0160576 0.00456265 0.0107582
                ]
                inertiaMatrix [
                  6.2e-07 1.47e-06 1.15e-06
                  2.6e-07 4.7e-07 1.3e-07
                ]
              }
            }
          }
          HingeJoint {
            jointParameters HingeJointParameters {
              axis -1 0 0
              anchor 0.02675 0.010265 0.04005
            }
            device [
              PositionSensor {
                name "BR_shoulder_joint_sensor"
              }
            ]
            endPoint Solid {
              translation 0.02675 0.010265 0.04005
              rotation 1.197885677515365e-21 1 0 1.570796
              children [
                Shape {
                  appearance DEF BR_shoulder_link_material PBRAppearance {
                    baseColor 0.752941 0 0
                    roughness 1
                    metalness 0
                  }
                  geometry DEF BR_shoulder_link Mesh {
                    url [
                      "../protos/URDF_MOSAC_V3/meshes/BR_shoulder_link.STL"
                    ]
                  }
                }
              ]
              name "BR_shoulder_link"
              physics Physics {
                density -1
                mass 0.014229
                centerOfMass [
                  -1.943e-05 0.016128 0.0133504
                ]
                inertiaMatrix [
                  1.41e-06 4.67e-06 5.4e-06
                  -6e-08 -3.1e-07 2.1e-07
                ]
              }
            }
          }
        ]
        name "BBR_link"
        physics Physics {
          density -1
          mass 0.146948
          centerOfMass [
            0.00578645 -0.00044528 0.0309194
          ]
          inertiaMatrix [
            5.466e-05 4.875e-05 3.354e-05
            4.6e-07 -6.9e-07 7.3e-07
          ]
        }
      }
    }
    HingeJoint {
      jointParameters HingeJointParameters {
        anchor 0.095 0.05275 0.0032
        dampingConstant 0.673885
      }
      device [
        RotationalMotor {
          name "BFL_joint"
        }
        PositionSensor {
          name "BFL_joint_sensor"
        }
      ]
      endPoint Solid {
        translation 0.095 0.05275 0.0032
        rotation 0.5773502691896258 0.5773502691896255 0.5773502691896258 2.0943949999999996
        children [
          Shape {
            appearance DEF BFL_link_material PBRAppearance {
              baseColor 0.792157 0.819608 0.933333
              roughness 1
              metalness 0
            }
            geometry DEF BFL_link Mesh {
              url [
                "../protos/URDF_MOSAC_V3/meshes/BFL_link.STL"
              ]
            }
          }
          HingeJoint {
            jointParameters HingeJointParameters {
              axis -1 0 0
              anchor 0.02675 0.010265 0.02005
              dampingConstant 0.673885
            }
            device [
              RotationalMotor {
                name "FL_servo_femur_joint"
              }
              PositionSensor {
                name "FL_servo_femur_joint_sensor"
              }
            ]
            endPoint Solid {
              translation 0.02675 0.010265 0.02005
              rotation 0 1 0 1.570796
              children [
                Shape {
                  appearance DEF FL_servo_femur_link_material PBRAppearance {
                    roughness 1
                    metalness 0
                  }
                  geometry DEF FL_servo_femur_link Mesh {
                    url [
                      "../protos/URDF_MOSAC_V3/meshes/FL_servo_femur_link.STL"
                    ]
                  }
                }
                HingeJoint {
                  jointParameters HingeJointParameters {
                    axis 0 0 1
                    anchor 0.07355 -0.067752 0.02225
                  }
                  device [
                    PositionSensor {
                      name "FL_tibia_joint_sensor"
                    }
                  ]
                  endPoint Solid {
                    translation 0.07355 -0.067752 0.02225
                    children [
                      DEF PFL Solid {
                        translation -0.074 -0.085 0
                      }
                      TouchSensor {
                        name "touch_FL"
                        boundingObject DEF Paw_FL Pose {
                          translation -0.074246 -0.068 0
                          children [
                            Cylinder {
                              height 0.016
                              radius 0.01725
                            }
                          ]
                        }
                      }
                      Shape {
                        appearance DEF FL_tibia_link_material PBRAppearance {
                          baseColor 0.243137 0.243137 0.243137
                          roughness 1
                          metalness 0
                        }
                        geometry DEF FL_tibia_link Mesh {
                          url [
                            "../protos/URDF_MOSAC_V3/meshes/FL_tibia_link.STL"
                          ]
                        }
                      }
                      HingeJoint {
                        jointParameters HingeJointParameters {
                          axis 0 0 1
                          anchor 0.019092 0.019092 -0.00425
                        }
                        device [
                          PositionSensor {
                            name "FL_rotula_grande_tibia_joint_sensor"
                          }
                        ]
                        endPoint Solid {
                          translation 0.019092 0.019092 -0.00425
                          children [
                            Shape {
                              appearance DEF FL_rotula_grande_tibia_link_material PBRAppearance {
                                baseColor 0.792157 0.603922 0.227451
                                roughness 1
                                metalness 0
                              }
                              geometry DEF FL_rotula_grande_tibia_link Mesh {
                                url [
                                  "../protos/URDF_MOSAC_V3/meshes/FL_rotula_grande_tibia_link.STL"
                                ]
                              }
                            }
                            HingeJoint {
                              jointParameters HingeJointParameters {
                                axis 0 0 1
                                anchor -0.07355 0.067752 0
                              }
                              device [
                                PositionSensor {
                                  name "FL_rotula_grande_shoulder_joint_sensor"
                                }
                              ]
                              endPoint SolidReference {
                                solidName "FL_shoulder_link"
                              }
                            }
                          ]
                          name "FL_rotula_grande_tibia_link"
                          physics Physics {
                            density -1
                            mass 0.0250314
                            centerOfMass [
                              -0.0392972 0.0309149 0
                            ]
                            inertiaMatrix [
                              1.66e-05 2.652e-05 4.294e-05
                              -2.048e-05 0 0
                            ]
                          }
                        }
                      }
                    ]
                    name "FL_tibia_link"
                    boundingObject USE Paw_FL
                    physics Physics {
                      density -1
                      mass 0.0287979
                      centerOfMass [
                        -0.0301101 -0.0353435 -0.00106887
                      ]
                      inertiaMatrix [
                        4.165e-05 3.624e-05 7.605e-05
                        3.683e-05 -1.43e-06 -1.68e-06
                      ]
                    }
                  }
                }
              ]
              name "FL_servo_femur_link"
              physics Physics {
                density -1
                mass 0.0324892
                centerOfMass [
                  0.0279237 -0.0219658 0.0170025
                ]
                inertiaMatrix [
                  2.368e-05 3.618e-05 5.523e-05
                  -2.58e-05 4.72e-06 -3.71e-06
                ]
              }
            }
          }
          HingeJoint {
            jointParameters HingeJointParameters {
              axis -1 0 0
              anchor 0.02375 -0.010265 0.04005
              dampingConstant 0.673885
            }
            device [
              RotationalMotor {
                name "FL_servo_tibia_joint"
              }
              PositionSensor {
                name "FL_servo_tibia_joint_sensor"
              }
            ]
            endPoint Solid {
              translation 0.02375 -0.010265 0.04005
              rotation 3.925231788082348e-17 1 3.925231788082348e-17 1.570796
              children [
                Shape {
                  appearance DEF FL_servo_tibia_link_material PBRAppearance {
                    baseColor 0.898039 0.917647 0.929412
                    roughness 1
                    metalness 0
                  }
                  geometry DEF FL_servo_tibia_link Mesh {
                    url [
                      "../protos/URDF_MOSAC_V3/meshes/FL_servo_tibia_link.STL"
                    ]
                  }
                }
                HingeJoint {
                  jointParameters HingeJointParameters {
                    axis 0 0 1
                    anchor -0.022981 0.006918 0.0175
                  }
                  device [
                    PositionSensor {
                      name "FL_rotula_chica_servo_joint_sensor"
                    }
                  ]
                  endPoint Solid {
                    translation -0.022981 0.006918 0.0175
                    children [
                      Shape {
                        appearance DEF FL_rotula_chica_servo_link_material PBRAppearance {
                          baseColor 0.792157 0.603922 0.227451
                          roughness 1
                          metalness 0
                        }
                        geometry DEF FL_rotula_chica_servo_link Mesh {
                          url [
                            "../protos/URDF_MOSAC_V3/meshes/FL_rotula_chica_servo_link.STL"
                          ]
                        }
                      }
                      HingeJoint {
                        jointParameters HingeJointParameters {
                          axis 0 0 1
                          anchor 0.023889 0.032704 0
                        }
                        device [
                          PositionSensor {
                            name "FL_rotula_chica_shoulder_joint_sensor"
                          }
                        ]
                        endPoint SolidReference {
                          solidName "FL_shoulder_link"
                        }
                      }
                    ]
                    name "FL_rotula_chica_servo_link"
                    physics Physics {
                      density -1
                      mass 0.0212414
                      centerOfMass [
                        0.0106375 0.017231 0
                      ]
                      inertiaMatrix [
                        4.57e-06 2.01e-06 6.45e-06
                        2.56e-06 0 0
                      ]
                    }
                  }
                }
              ]
              name "FL_servo_tibia_link"
              physics Physics {
                density -1
                mass 0.00954161
                centerOfMass [
                  -0.0163112 0.00355117 0.0107582
                ]
                inertiaMatrix [
                  5.9e-07 1.5e-06 1.15e-06
                  -2.1e-07 -4.7e-07 1e-07
                ]
              }
            }
          }
          HingeJoint {
            jointParameters HingeJointParameters {
              anchor 0.02675 0.010265 0.02005
            }
            device [
              PositionSensor {
                name "FL_shoulder_joint_sensor"
              }
            ]
            endPoint Solid {
              translation 0.02675 0.010265 0.02005
              rotation 0 1 0 1.570796
              children [
                Shape {
                  appearance DEF FL_shoulder_link_material PBRAppearance {
                    baseColor 0.752941 0 0
                    roughness 1
                    metalness 0
                  }
                  geometry DEF FL_shoulder_link Mesh {
                    url [
                      "../protos/URDF_MOSAC_V3/meshes/FL_shoulder_link.STL"
                    ]
                  }
                }
              ]
              name "FL_shoulder_link"
              physics Physics {
                density -1
                mass 0.0145048
                centerOfMass [
                  -0.00062791 0.0161822 0.0131832
                ]
                inertiaMatrix [
                  1.46e-06 4.76e-06 5.5e-06
                  2.9e-07 2.5e-07 2.2e-07
                ]
              }
            }
          }
        ]
        name "BFL_link"
        physics Physics {
          density -1
          mass 0.146948
          centerOfMass [
            0.00579589 0.00029828 0.0309194
          ]
          inertiaMatrix [
            5.468e-05 4.873e-05 3.354e-05
            -3e-07 -7.1e-07 -7.2e-07
          ]
        }
      }
    }
    HingeJoint {
      jointParameters HingeJointParameters {
        anchor -0.095 0.05275 0.0032
        dampingConstant 0.673885
      }
      device [
        RotationalMotor {
          name "BBL_joint"
        }
        PositionSensor {
          name "BBL_joint_sensor"
        }
      ]
      endPoint Solid {
        translation -0.095 0.05275 0.0032
        rotation 0.5773502691896258 0.5773502691896257 0.5773502691896257 2.094395
        children [
          Shape {
            appearance DEF BBL_link_material PBRAppearance {
              roughness 1
              metalness 0
            }
            geometry DEF BBL_link Mesh {
              url [
                "../protos/URDF_MOSAC_V3/meshes/BBL_link.STL"
              ]
            }
          }
          HingeJoint {
            jointParameters HingeJointParameters {
              axis -1 0 0
              anchor 0.02675 0.010265 -0.04005
              dampingConstant 0.673885
            }
            device [
              RotationalMotor {
                name "BL_servo_femur_joint"
              }
              PositionSensor {
                name "BL_servo_femur_joint_sensor"
              }
            ]
            endPoint Solid {
              translation 0.02675 0.010265 -0.04005
              rotation 0 1 0 1.570796
              children [
                Shape {
                  appearance DEF BL_servo_femur_link_material PBRAppearance {
                    roughness 1
                    metalness 0
                  }
                  geometry DEF BL_servo_femur_link Mesh {
                    url [
                      "../protos/URDF_MOSAC_V3/meshes/BL_servo_femur_link.STL"
                    ]
                  }
                }
                HingeJoint {
                  jointParameters HingeJointParameters {
                    axis 0 0 1
                    anchor 0.07355 -0.067752 0.02225
                  }
                  device [
                    PositionSensor {
                      name "BL_tibia_joint_sensor"
                    }
                  ]
                  endPoint Solid {
                    translation 0.07355 -0.067752 0.02225
                    children [
                      DEF PBL Solid {
                        translation -0.074 -0.085 0
                      }
                      TouchSensor {
                        name "touch_BL"
                        boundingObject DEF Paw_BL Pose {
                          translation -0.074246 -0.068 0
                          children [
                            Cylinder {
                              height 0.016
                              radius 0.01725
                            }
                          ]
                        }
                      }
                      Shape {
                        appearance DEF BL_tibia_link_material PBRAppearance {
                          roughness 1
                          metalness 0
                        }
                        geometry DEF BL_tibia_link Mesh {
                          url [
                            "../protos/URDF_MOSAC_V3/meshes/BL_tibia_link.STL"
                          ]
                        }
                      }
                      HingeJoint {
                        jointParameters HingeJointParameters {
                          axis 0 0 -1
                          anchor 0.019092 0.019092 -0.00425
                        }
                        device [
                          PositionSensor {
                            name "BL_rotula_grande_tibia_joint_sensor"
                          }
                        ]
                        endPoint Solid {
                          translation 0.019092 0.019092 -0.00425
                          rotation 0 0 -1 0
                          children [
                            Shape {
                              appearance DEF BL_rotula_grande_tibia_link_material PBRAppearance {
                                baseColor 0.792157 0.603922 0.227451
                                roughness 1
                                metalness 0
                              }
                              geometry DEF BL_rotula_grande_tibia_link Mesh {
                                url [
                                  "../protos/URDF_MOSAC_V3/meshes/BL_rotula_grande_tibia_link.STL"
                                ]
                              }
                            }
                            HingeJoint {
                              jointParameters HingeJointParameters {
                                axis 0 0 -1
                                anchor -0.07355 0.067752 0
                              }
                              device [
                                PositionSensor {
                                  name "BL_rotula_grande_shoulder_joint_sensor"
                                }
                              ]
                              endPoint SolidReference {
                                solidName "BL_shoulder_link"
                              }
                            }
                          ]
                          name "BL_rotula_grande_tibia_link"
                          physics Physics {
                            density -1
                            mass 0.0250314
                            centerOfMass [
                              -0.0392972 0.0309149 0
                            ]
                            inertiaMatrix [
                              1.66e-05 2.652e-05 4.294e-05
                              -2.048e-05 0 0
                            ]
                          }
                        }
                      }
                    ]
                    name "BL_tibia_link"
                    boundingObject USE Paw_BL
                    physics Physics {
                      density -1
                      mass 0.0286325
                      centerOfMass [
                        -0.0303855 -0.0356662 -0.0009959
                      ]
                      inertiaMatrix [
                        4.11e-05 3.583e-05 7.515e-05
                        3.639e-05 -1.33e-06 -1.56e-06
                      ]
                    }
                  }
                }
              ]
              name "BL_servo_femur_link"
              physics Physics {
                density -1
                mass 0.0324892
                centerOfMass [
                  0.0279237 -0.0219658 0.0170025
                ]
                inertiaMatrix [
                  2.368e-05 3.618e-05 5.523e-05
                  -2.58e-05 4.72e-06 -3.71e-06
                ]
              }
            }
          }
          HingeJoint {
            jointParameters HingeJointParameters {
              axis -1 0 0
              anchor 0.02375 -0.010265 -0.02005
              dampingConstant 0.673885
            }
            device [
              RotationalMotor {
                name "BL_servo_tibia_joint"
              }
              PositionSensor {
                name "BL_servo_tibia_joint_sensor"
              }
            ]
            endPoint Solid {
              translation 0.02375 -0.010265 -0.02005
              rotation 7.486785484471032e-23 1 7.486785484471032e-23 1.570796
              children [
                Shape {
                  appearance DEF BL_servo_tibia_link_material PBRAppearance {
                    baseColor 0.898039 0.917647 0.929412
                    roughness 1
                    metalness 0
                  }
                  geometry DEF BL_servo_tibia_link Mesh {
                    url [
                      "../protos/URDF_MOSAC_V3/meshes/BL_servo_tibia_link.STL"
                    ]
                  }
                }
                HingeJoint {
                  jointParameters HingeJointParameters {
                    axis 0 0 1
                    anchor -0.022981 0.006918 0.0175
                  }
                  device [
                    PositionSensor {
                      name "BL_rotula_chica_servo_joint_sensor"
                    }
                  ]
                  endPoint Solid {
                    translation -0.022981 0.006918 0.0175
                    children [
                      Shape {
                        appearance DEF BL_rotula_chica_servo_link_material PBRAppearance {
                          baseColor 0.792157 0.603922 0.227451
                          roughness 1
                          metalness 0
                        }
                        geometry DEF BL_rotula_chica_servo_link Mesh {
                          url [
                            "../protos/URDF_MOSAC_V3/meshes/BL_rotula_chica_servo_link.STL"
                          ]
                        }
                      }
                      HingeJoint {
                        jointParameters HingeJointParameters {
                          axis 0 0 1
                          anchor 0.023889 0.032704 0
                        }
                        device [
                          PositionSensor {
                            name "BL_rotula_chica_shoulder_joint_sensor"
                          }
                        ]
                        endPoint SolidReference {
                          solidName "BL_shoulder_link"
                        }
                      }
                    ]
                    name "BL_rotula_chica_servo_link"
                    physics Physics {
                      density -1
                      mass 0.0212414
                      centerOfMass [
                        0.0106375 0.017231 0
                      ]
                      inertiaMatrix [
                        4.57e-06 2.01e-06 6.45e-06
                        2.56e-06 0 0
                      ]
                    }
                  }
                }
              ]
              name "BL_servo_tibia_link"
              physics Physics {
                density -1
                mass 0.00954161
                centerOfMass [
                  -0.0163112 0.00355117 0.0107582
                ]
                inertiaMatrix [
                  5.9e-07 1.5e-06 1.15e-06
                  -2.1e-07 -4.7e-07 1e-07
                ]
              }
            }
          }
          HingeJoint {
            jointParameters HingeJointParameters {
              anchor 0.02675 0.010265 -0.04005
            }
            device [
              PositionSensor {
                name "BL_shoulder_joint_sensor"
              }
            ]
            endPoint Solid {
              translation 0.02675 0.010265 -0.04005
              rotation 3.0665873344393355e-19 1 -1.5332936672196677e-19 1.5707959999999996
              children [
                Shape {
                  appearance DEF BL_shoulder_link_material PBRAppearance {
                    baseColor 0.752941 0 0
                    roughness 1
                    metalness 0
                  }
                  geometry DEF BL_shoulder_link Mesh {
                    url [
                      "../protos/URDF_MOSAC_V3/meshes/BL_shoulder_link.STL"
                    ]
                  }
                }
              ]
              name "BL_shoulder_link"
              physics Physics {
                density -1
                mass 0.0142291
                centerOfMass [
                  -0.00098009 0.0160982 0.0133504
                ]
                inertiaMatrix [
                  1.43e-06 4.65e-06 5.4e-06
                  2.6e-07 2.9e-07 2.3e-07
                ]
              }
            }
          }
        ]
        name "BBL_link"
        physics Physics {
          density -1
          mass 0.146948
          centerOfMass [
            0.00579566 0.0003027 -0.0309194
          ]
          inertiaMatrix [
            5.468e-05 4.873e-05 3.354e-05
            -3.1e-07 7.8e-07 -6.4e-07
          ]
        }
      }
    }
  ]
  name "URDFMOSACV3"
  boundingObject Box {
    size 0.36 0.135 0.085
  }
  physics Physics {
    density -1
    mass 1.30187
    centerOfMass [
      0.00020256 0.00078097 -0.00252457
    ]
    inertiaMatrix [
      0.00317525 0.0102862 0.0115208
      -3.6e-06 -7.65e-06 -3.19e-06
    ]
  }
  controller "MOSAC_Controller"
  supervisor TRUE
}
Floor {
}
