#VRML_SIM R2023b utf8

EXTERNPROTO "https://raw.githubusercontent.com/cyberbotics/webots/R2023b/projects/objects/backgrounds/protos/TexturedBackground.proto"
EXTERNPROTO "https://raw.githubusercontent.com/cyberbotics/webots/R2023b/projects/objects/backgrounds/protos/TexturedBackgroundLight.proto"
EXTERNPROTO "https://raw.githubusercontent.com/cyberbotics/webots/R2023b/projects/objects/floors/protos/Floor.proto"

WorldInfo {
  basicTimeStep 10
  contactProperties [
    ContactProperties {
      rollingFriction 0.05 0 0
      maxContactJoints 10000
    }
  ]
}
Viewpoint {
  orientation 0.2757738180973987 -0.10870915481459108 -0.9550555590705078 3.9900410397471946
  position 0.9425909977193792 -1.0216163746619233 0.8041517625024657
}
TexturedBackground {
}
TexturedBackgroundLight {
}
DEF MOSAC Robot {
  translation 0 0 0.14
  children [
    Gyro {
      translation 0 -0.005 0.036
      rotation 0 0 1 3.14159
    }
    Accelerometer {
      translation 0 -0.005 0.036
      rotation 0 0 1 3.14159
    }
    Shape {
      appearance DEF chasis_base_link_material PBRAppearance {
        baseColor 0.298039 0.298039 0.298039
        roughness 1
        metalness 0
      }
      geometry DEF chasis_base_link Mesh {
        url [
          "../protos/URDF_MOSAC_V3/meshes/chasis_base_link.STL"
        ]
      }
    }
    HingeJoint {
      jointParameters HingeJointParameters {
        anchor 0.095 -0.05275 0.0032
        dampingConstant 0.673885
      }
      device [
        RotationalMotor {
          name "BFR_joint"
          maxTorque 5.7
        }
        PositionSensor {
          name "BFR_joint_sensor"
        }
      ]
      endPoint Solid {
        translation 0.095 -0.05275 0.0032
        rotation 0.5773502691896257 -0.5773502691896257 -0.5773502691896257 2.094395
        children [
          Shape {
            appearance DEF BFR_link_material PBRAppearance {
              baseColor 0.792157 0.819608 0.933333
              roughness 1
              metalness 0
            }
            geometry DEF BFR_link Mesh {
              url [
                "../protos/URDF_MOSAC_V3/meshes/BFR_link.STL"
              ]
            }
          }
          HingeJoint {
            jointParameters HingeJointParameters {
              anchor 0.02675 0.010265 -0.02005
              dampingConstant 0.673885
            }
            device [
              RotationalMotor {
                name "FR_servo_femur_joint"
                maxTorque 5.7
              }
              PositionSensor {
                name "FR_servo_femur_joint_sensor"
              }
            ]
            endPoint Solid {
              translation 0.02675 0.010265 -0.02005
              rotation 0 1 0 1.5708
              children [
                Shape {
                  appearance DEF FR_servo_femur_link_material PBRAppearance {
                    roughness 1
                    metalness 0
                  }
                  geometry DEF FR_servo_femur_link Mesh {
                    url [
                      "../protos/URDF_MOSAC_V3/meshes/FR_servo_femur_link.STL"
                    ]
                  }
                }
                HingeJoint {
                  jointParameters HingeJointParameters {
                    axis 0 0 -1
                    anchor -0.07355 -0.067752 0.02225
                  }
                  device [
                    PositionSensor {
                      name "FR_tibia_joint_sensor"
                    }
                  ]
                  endPoint Solid {
                    translation -0.07355 -0.067752 0.02225
                    rotation 0 0 -1 0
                    children [
                      Shape {
                        appearance DEF FR_tibia_link_material PBRAppearance {
                          roughness 1
                          metalness 0
                        }
                        geometry DEF FR_tibia_link Mesh {
                          url [
                            "../protos/URDF_MOSAC_V3/meshes/FR_tibia_link.STL"
                          ]
                        }
                      }
                      HingeJoint {
                        jointParameters HingeJointParameters {
                          axis 0 0 -1
                          anchor -0.019092 0.019092 -0.00425
                        }
                        device [
                          PositionSensor {
                            name "FR_rotula_grande_tibia_joint_sensor"
                          }
                        ]
                        endPoint Solid {
                          translation -0.019092 0.019092 -0.00425
                          rotation 0 0 -1 0
                          children [
                            Shape {
                              appearance DEF FR_rotula_grande_tibia_link_material PBRAppearance {
                                baseColor 0.79216 0.60392 0.22745
                                roughness 1
                                metalness 0
                              }
                              geometry DEF FR_rotula_grande_tibia_link Mesh {
                                url [
                                  "../protos/URDF_MOSAC_V3/meshes/FR_rotula_grande_tibia_link.STL"
                                ]
                              }
                            }
                            HingeJoint {
                              jointParameters HingeJointParameters {
                                axis 0 0 -1
                                anchor 0.07355 0.067752 0
                              }
                              device [
                                PositionSensor {
                                  name "FR_rotula_grande_shoulder_joint_sensor"
                                }
                              ]
                              endPoint SolidReference {
                                solidName "FR_shoulder_link"
                              }
                            }
                          ]
                          name "FR_rotula_grande_tibia_link"
                          physics Physics {
                            density -1
                            mass 0.025031
                            centerOfMass [
                              0.036775 0.033876 0
                            ]
                            inertiaMatrix [
                              2.1948e-06 2.5003e-06 4.5145e-06
                              -1.8582e-06 -2.3509e-20 -2.2887e-20
                            ]
                          }
                        }
                      }
                    ]
                    name "FR_tibia_link"
                    boundingObject Pose {
                      translation 0.074 -0.065 0
                      children [
                        Cylinder {
                          height 0.02
                          radius 0.02
                        }
                      ]
                    }
                    physics Physics {
                      density -1
                      mass 0.028632
                      centerOfMass [
                        0.033067 -0.033197 -0.000996
                      ]
                      inertiaMatrix [
                        1.1409e-05 1.81e-05 2.8685e-05
                        1.3197e-05 -2.0267e-07 2.003e-07
                      ]
                    }
                  }
                }
              ]
              name "FR_servo_femur_link"
              physics Physics {
                density -1
                mass 0.032489
                centerOfMass [
                  -0.026115 -0.024055 0.017002
                ]
                inertiaMatrix [
                  9.1106e-06 1.046e-05 1.829e-05
                  -8.2102e-06 4.3945e-07 4.0437e-07
                ]
              }
            }
          }
          HingeJoint {
            jointParameters HingeJointParameters {
              anchor 0.02375 -0.010265 -0.04005
              dampingConstant 0.673885
            }
            device [
              RotationalMotor {
                name "FR_servo_tibia_joint"
                maxTorque 5.7
              }
              PositionSensor {
                name "FR_servo_tibia_joint_sensor"
              }
            ]
            endPoint Solid {
              translation 0.02375 -0.010265 -0.04005
              rotation 0 1 0 1.570796
              children [
                Shape {
                  appearance DEF FR_servo_tibia_link_material PBRAppearance {
                    baseColor 0.898039 0.917647 0.929412
                    roughness 1
                    metalness 0
                  }
                  geometry DEF FR_servo_tibia_link Mesh {
                    url [
                      "../protos/URDF_MOSAC_V3/meshes/FR_servo_tibia_link.STL"
                    ]
                  }
                }
                HingeJoint {
                  jointParameters HingeJointParameters {
                    axis 0 0 -1
                    anchor 0.022981 0.006918 0.0175
                  }
                  device [
                    PositionSensor {
                      name "FR_rotula_chica_servo_joint_sensor"
                    }
                  ]
                  endPoint Solid {
                    translation 0.022981 0.006918 0.0175
                    rotation 0 0 -1 0
                    children [
                      Shape {
                        appearance DEF FR_rotula_chica_servo_link_material PBRAppearance {
                          baseColor 0.792157 0.603922 0.227451
                          roughness 1
                          metalness 0
                        }
                        geometry DEF FR_rotula_chica_servo_link Mesh {
                          url [
                            "../protos/URDF_MOSAC_V3/meshes/FR_rotula_chica_servo_link.STL"
                          ]
                        }
                      }
                      HingeJoint {
                        jointParameters HingeJointParameters {
                          axis 0 0 -1
                          anchor -0.023889 0.032704 0
                        }
                        device [
                          PositionSensor {
                            name "FR_rotula_chica_shoulder_joint_sensor"
                          }
                        ]
                        endPoint SolidReference {
                          solidName "FR_shoulder_link"
                        }
                      }
                    ]
                    name "FR_rotula_chica_servo_link"
                    physics Physics {
                      density -1
                      mass 0.021241
                      centerOfMass [
                        -0.011945 0.016352 0
                      ]
                      inertiaMatrix [
                        1.378944e-06 9.354773e-07 2.188758e-06
                        6.945552e-07 2.969534e-21 -7.430566e-21
                      ]
                    }
                  }
                }
              ]
              name "FR_servo_tibia_link"
              physics Physics {
                density -1
                mass 0.009541
                centerOfMass [
                  0.015983 0.004816 0.010758
                ]
                inertiaMatrix [
                  1.881741e-07 4.579952e-07 4.800257e-07
                  -9.315114e-08 -6.305284e-09 -1.879625e-09
                ]
              }
            }
          }
          HingeJoint {
            jointParameters HingeJointParameters {
              axis -1 0 0
              anchor 0.02675 0.010265 -0.02005
            }
            device [
              PositionSensor {
                name "FR_shoulder_joint_sensor"
              }
            ]
            endPoint Solid {
              translation 0.02675 0.010265 -0.02005
              rotation 0 1 0 1.570796
              children [
                Shape {
                  appearance DEF FR_shoulder_link_material PBRAppearance {
                    baseColor 0.752941 0 0
                    roughness 1
                    metalness 0
                  }
                  geometry DEF FR_shoulder_link Mesh {
                    url [
                      "../protos/URDF_MOSAC_V3/meshes/FR_shoulder_link.STL"
                    ]
                  }
                }
              ]
              name "FR_shoulder_link"
              physics Physics {
                density -1
                mass 0.014229
                centerOfMass [
                  -0.000274 0.016126 0.01335
                ]
                inertiaMatrix [
                  9.001932e-07 8.699501e-07 1.559908e-06
                  3.622225e-08 4.929724e-09 2.805351e-08
                ]
              }
            }
          }
        ]
        name "BFR_link"
        physics Physics {
          density -1
          mass 0.146947
          centerOfMass [
            0.005804 -2e-06 -0.030919
          ]
          inertiaMatrix [
            2.307477e-05 2.031684e-05 8.628932e-06
            -2.913178e-09 -1.151036e-09 8.251735e-10
          ]
        }
      }
    }
    HingeJoint {
      jointParameters HingeJointParameters {
        anchor -0.095 -0.05275 0.0032
        dampingConstant 0.673885
      }
      device [
        RotationalMotor {
          name "BBR_joint"
          maxTorque 5.7
        }
        PositionSensor {
          name "BBR_joint_sensor"
        }
      ]
      endPoint Solid {
        translation -0.095 -0.05275 0.0032
        rotation 0.5773502691896257 -0.5773502691896257 -0.5773502691896257 2.094395
        children [
          Shape {
            appearance DEF BBR_link_material PBRAppearance {
              baseColor 0.792157 0.819608 0.933333
              roughness 1
              metalness 0
            }
            geometry DEF BBR_link Mesh {
              url [
                "../protos/URDF_MOSAC_V3/meshes/BBR_link.STL"
              ]
            }
          }
          HingeJoint {
            jointParameters HingeJointParameters {
              anchor 0.02675 0.010265 0.04005
              dampingConstant 0.673885
            }
            device [
              RotationalMotor {
                name "BR_servo_femur_joint"
                maxTorque 5.7
              }
              PositionSensor {
                name "BR_servo_femur_joint_sensor"
              }
            ]
            endPoint Solid {
              translation 0.02675 0.010265 0.04005
              rotation 0 1 0 1.570796
              children [
                Shape {
                  appearance DEF BR_servo_femur_link_material PBRAppearance {
                    baseColor 0.298039 0.298039 0.298039
                    roughness 1
                    metalness 0
                  }
                  geometry DEF BR_servo_femur_link Mesh {
                    url [
                      "../protos/URDF_MOSAC_V3/meshes/BR_servo_femur_link.STL"
                    ]
                  }
                }
                HingeJoint {
                  jointParameters HingeJointParameters {
                    axis 0 0 -1
                    anchor -0.07355 -0.067752 0.02225
                  }
                  device [
                    PositionSensor {
                      name "BR_tibia_joint_sensor"
                    }
                  ]
                  endPoint Solid {
                    translation -0.07355 -0.067752 0.02225
                    rotation 0 0 -1 0
                    children [
                      Shape {
                        appearance DEF BR_tibia_link_material PBRAppearance {
                          roughness 1
                          metalness 0
                        }
                        geometry DEF BR_tibia_link Mesh {
                          url [
                            "../protos/URDF_MOSAC_V3/meshes/BR_tibia_link.STL"
                          ]
                        }
                      }
                      HingeJoint {
                        jointParameters HingeJointParameters {
                          axis 0 0 1
                          anchor -0.019092 0.019092 -0.00425
                        }
                        device [
                          PositionSensor {
                            name "BR_rotula_grande_tibia_joint_sensor"
                          }
                        ]
                        endPoint Solid {
                          translation -0.019092 0.019092 -0.00425
                          children [
                            Shape {
                              appearance DEF BR_rotula_grande_tibia_link_material PBRAppearance {
                                baseColor 0.776471 0.756863 0.737255
                                roughness 1
                                metalness 0
                              }
                              geometry DEF BR_rotula_grande_tibia_link Mesh {
                                url [
                                  "../protos/URDF_MOSAC_V3/meshes/BR_rotula_grande_tibia_link.STL"
                                ]
                              }
                            }
                            HingeJoint {
                              jointParameters HingeJointParameters {
                                axis 0 0 1
                                anchor 0.07355 0.067752 0
                              }
                              device [
                                PositionSensor {
                                  name "BR_rotula_grande_shoulder_joint_sensor"
                                }
                              ]
                              endPoint SolidReference {
                                solidName "BR_shoulder_link"
                              }
                            }
                          ]
                          name "BR_rotula_grande_tibia_link"
                          physics Physics {
                            density -1
                            mass 0.025031
                            centerOfMass [
                              0.036775 0.033876 0
                            ]
                            inertiaMatrix [
                              2.194795e-06 2.50031e-06 4.514487e-06
                              -1.858208e-06 -6.852268e-21 -8.637155e-21
                            ]
                          }
                        }
                      }
                    ]
                    name "BR_tibia_link"
                    boundingObject Pose {
                      translation 0.074 -0.065 0
                      children [
                        Cylinder {
                          height 0.02
                          radius 0.02
                        }
                      ]
                    }
                    physics Physics {
                      density -1
                      mass 0.028632
                      centerOfMass [
                        0.033067 -0.033197 -0.000996
                      ]
                      inertiaMatrix [
                        1.140896e-05 1.809984e-05 2.868461e-05
                        1.319702e-05 -2.026665e-07 2.003045e-07
                      ]
                    }
                  }
                }
              ]
              name "BR_servo_femur_link"
              physics Physics {
                density -1
                mass 0.032489
                centerOfMass [
                  -0.026115 -0.024055 0.017002
                ]
                inertiaMatrix [
                  9.110616e-06 1.046034e-05 1.829023e-05
                  -8.210221e-06 4.394534e-07 4.043732e-07
                ]
              }
            }
          }
          HingeJoint {
            jointParameters HingeJointParameters {
              anchor 0.02375 -0.010265 0.02005
              dampingConstant 0.673885
            }
            device [
              RotationalMotor {
                name "BR_servo_tibia_joint"
                maxTorque 5.7
              }
              PositionSensor {
                name "BR_servo_tibia_joint_sensor"
              }
            ]
            endPoint Solid {
              translation 0.02375 -0.010265 0.02005
              rotation 0 1 0 1.570796
              children [
                Shape {
                  appearance DEF BR_servo_tibia_link_material PBRAppearance {
                    baseColor 0.898039 0.917647 0.929412
                    roughness 1
                    metalness 0
                  }
                  geometry DEF BR_servo_tibia_link Mesh {
                    url [
                      "../protos/URDF_MOSAC_V3/meshes/BR_servo_tibia_link.STL"
                    ]
                  }
                }
                HingeJoint {
                  jointParameters HingeJointParameters {
                    axis 0 0 -1
                    anchor 0.022981 0.006918 0.0175
                  }
                  device [
                    PositionSensor {
                      name "BR_rotula_chica_servo_joint_sensor"
                    }
                  ]
                  endPoint Solid {
                    translation 0.022981 0.006918 0.0175
                    rotation 0 0 -1 0
                    children [
                      Shape {
                        appearance DEF BR_rotula_chica_servo_link_material PBRAppearance {
                          baseColor 0.792157 0.603922 0.227451
                          roughness 1
                          metalness 0
                        }
                        geometry DEF BR_rotula_chica_servo_link Mesh {
                          url [
                            "../protos/URDF_MOSAC_V3/meshes/BR_rotula_chica_servo_link.STL"
                          ]
                        }
                      }
                      HingeJoint {
                        jointParameters HingeJointParameters {
                          axis 0 0 -1
                          anchor -0.023889 0.032704 0
                        }
                        device [
                          PositionSensor {
                            name "BR_rotula_chica_shoulder_joint_sensor"
                          }
                        ]
                        endPoint SolidReference {
                          solidName "BR_shoulder_link"
                        }
                      }
                    ]
                    name "BR_rotula_chica_servo_link"
                    physics Physics {
                      density -1
                      mass 0.021241
                      centerOfMass [
                        -0.011945 0.016352 0
                      ]
                      inertiaMatrix [
                        1.378944e-06 9.354773e-07 2.188758e-06
                        6.945552e-07 6.994634e-21 -1.018934e-20
                      ]
                    }
                  }
                }
              ]
              name "BR_servo_tibia_link"
              physics Physics {
                density -1
                mass 0.009541
                centerOfMass [
                  0.015983 0.004816 0.010758
                ]
                inertiaMatrix [
                  1.881741e-07 4.579952e-07 4.800257e-07
                  -9.315114e-08 -6.305284e-09 -1.879625e-09
                ]
              }
            }
          }
          HingeJoint {
            jointParameters HingeJointParameters {
              axis -1 0 0
              anchor 0.02675 0.010265 0.04005
            }
            device [
              PositionSensor {
                name "BR_shoulder_joint_sensor"
              }
            ]
            endPoint Solid {
              translation 0.02675 0.010265 0.04005
              rotation 0 1 0 1.570796
              children [
                Shape {
                  appearance DEF BR_shoulder_link_material PBRAppearance {
                    baseColor 0.752941 0 0
                    roughness 1
                    metalness 0
                  }
                  geometry DEF BR_shoulder_link Mesh {
                    url [
                      "../protos/URDF_MOSAC_V3/meshes/BR_shoulder_link.STL"
                    ]
                  }
                }
              ]
              name "BR_shoulder_link"
              physics Physics {
                density -1
                mass 0.014229
                centerOfMass [
                  -0.000274 0.016126 0.01335
                ]
                inertiaMatrix [
                  9.001932e-07 8.699501e-07 1.559908e-06
                  3.622225e-08 4.929724e-09 2.805351e-08
                ]
              }
            }
          }
        ]
        name "BBR_link"
        physics Physics {
          density -1
          mass 0.146947
          centerOfMass [
            0.005804 2e-06 0.030919
          ]
          inertiaMatrix [
            2.307477e-05 2.031684e-05 8.628932e-06
            2.913178e-09 1.151036e-09 8.251735e-10
          ]
        }
      }
    }
    HingeJoint {
      jointParameters HingeJointParameters {
        anchor 0.095 0.05275 0.0032
        dampingConstant 0.673885
      }
      device [
        RotationalMotor {
          name "BFL_joint"
          maxTorque 5.7
        }
        PositionSensor {
          name "BFL_joint_sensor"
        }
      ]
      endPoint Solid {
        translation 0.095 0.05275 0.0032
        rotation 0.5773502691896257 0.5773502691896257 0.5773502691896257 2.094395
        children [
          Shape {
            appearance DEF BFL_link_material PBRAppearance {
              baseColor 0.792157 0.819608 0.933333
              roughness 1
              metalness 0
            }
            geometry DEF BFL_link Mesh {
              url [
                "../protos/URDF_MOSAC_V3/meshes/BFL_link.STL"
              ]
            }
          }
          HingeJoint {
            jointParameters HingeJointParameters {
              axis -1 0 0
              anchor 0.02675 0.010265 0.02005
              dampingConstant 0.673885
            }
            device [
              RotationalMotor {
                name "FL_servo_femur_joint"
                maxTorque 5.7
              }
              PositionSensor {
                name "FL_servo_femur_joint_sensor"
              }
            ]
            endPoint Solid {
              translation 0.02675 0.010265 0.02005
              rotation 0 1 0 1.570796
              children [
                Shape {
                  appearance DEF FL_servo_femur_link_material PBRAppearance {
                    roughness 1
                    metalness 0
                  }
                  geometry DEF FL_servo_femur_link Mesh {
                    url [
                      "../protos/URDF_MOSAC_V3/meshes/FL_servo_femur_link.STL"
                    ]
                  }
                }
                HingeJoint {
                  jointParameters HingeJointParameters {
                    axis 0 0 1
                    anchor 0.07355 -0.067752 0.02225
                  }
                  device [
                    PositionSensor {
                      name "FL_tibia_joint_sensor"
                    }
                  ]
                  endPoint Solid {
                    translation 0.07355 -0.067752 0.02225
                    children [
                      Shape {
                        appearance DEF FL_tibia_link_material PBRAppearance {
                          baseColor 0.243137 0.243137 0.243137
                          roughness 1
                          metalness 0
                        }
                        geometry DEF FL_tibia_link Mesh {
                          url [
                            "../protos/URDF_MOSAC_V3/meshes/FL_tibia_link.STL"
                          ]
                        }
                      }
                      HingeJoint {
                        jointParameters HingeJointParameters {
                          axis 0 0 1
                          anchor 0.019092 0.019092 -0.00425
                        }
                        device [
                          PositionSensor {
                            name "FL_rotula_grande_tibia_joint_sensor"
                          }
                        ]
                        endPoint Solid {
                          translation 0.019092 0.019092 -0.00425
                          children [
                            Shape {
                              appearance DEF FL_rotula_grande_tibia_link_material PBRAppearance {
                                baseColor 0.792157 0.603922 0.227451
                                roughness 1
                                metalness 0
                              }
                              geometry DEF FL_rotula_grande_tibia_link Mesh {
                                url [
                                  "../protos/URDF_MOSAC_V3/meshes/FL_rotula_grande_tibia_link.STL"
                                ]
                              }
                            }
                            HingeJoint {
                              jointParameters HingeJointParameters {
                                axis 0 0 1
                                anchor -0.07355 0.067752 0
                              }
                              device [
                                PositionSensor {
                                  name "FL_rotula_grande_shoulder_joint_sensor"
                                }
                              ]
                              endPoint SolidReference {
                                solidName "FL_shoulder_link"
                              }
                            }
                          ]
                          name "FL_rotula_grande_tibia_link"
                          physics Physics {
                            density -1
                            mass 0.025031
                            centerOfMass [
                              -0.036775 0.033876 0
                            ]
                            inertiaMatrix [
                              2.194795e-06 2.50031e-06 4.514487e-06
                              1.858208e-06 -3.751942e-22 2.231151e-22
                            ]
                          }
                        }
                      }
                    ]
                    name "FL_tibia_link"
                    boundingObject Pose {
                      translation -0.074 -0.065 0
                      children [
                        Cylinder {
                          height 0.02
                          radius 0.02
                        }
                      ]
                    }
                    physics Physics {
                      density -1
                      mass 0.028798
                      centerOfMass [
                        -0.032767 -0.032896 -0.001069
                      ]
                      inertiaMatrix [
                        1.142038e-05 1.811119e-05 2.868479e-05
                        -1.319703e-05 2.026317e-07 2.003751e-07
                      ]
                    }
                  }
                }
              ]
              name "FL_servo_femur_link"
              physics Physics {
                density -1
                mass 0.032489
                centerOfMass [
                  0.026132 -0.02407 0.017002
                ]
                inertiaMatrix [
                  9.109723e-06 1.04594e-05 1.828839e-05
                  8.209302e-06 -4.435056e-07 4.08107e-07
                ]
              }
            }
          }
          HingeJoint {
            jointParameters HingeJointParameters {
              axis -1 0 0
              anchor 0.02375 -0.010265 0.04005
              dampingConstant 0.673885
            }
            device [
              RotationalMotor {
                name "FL_servo_tibia_joint"
                maxTorque 5.7
              }
              PositionSensor {
                name "FL_servo_tibia_joint_sensor"
              }
            ]
            endPoint Solid {
              translation 0.02375 -0.010265 0.04005
              rotation 0 1 0 1.570796
              children [
                Shape {
                  appearance DEF FL_servo_tibia_link_material PBRAppearance {
                    baseColor 0.898039 0.917647 0.929412
                    roughness 1
                    metalness 0
                  }
                  geometry DEF FL_servo_tibia_link Mesh {
                    url [
                      "../protos/URDF_MOSAC_V3/meshes/FL_servo_tibia_link.STL"
                    ]
                  }
                }
                HingeJoint {
                  jointParameters HingeJointParameters {
                    axis 0 0 1
                    anchor -0.022981 0.006918 0.0175
                  }
                  device [
                    PositionSensor {
                      name "FL_rotula_chica_servo_joint_sensor"
                    }
                  ]
                  endPoint Solid {
                    translation -0.022981 0.006918 0.0175
                    children [
                      Shape {
                        appearance DEF FL_rotula_chica_servo_link_material PBRAppearance {
                          baseColor 0.792157 0.603922 0.227451
                          roughness 1
                          metalness 0
                        }
                        geometry DEF FL_rotula_chica_servo_link Mesh {
                          url [
                            "../protos/URDF_MOSAC_V3/meshes/FL_rotula_chica_servo_link.STL"
                          ]
                        }
                      }
                      HingeJoint {
                        jointParameters HingeJointParameters {
                          axis 0 0 1
                          anchor 0.023889 0.032704 0
                        }
                        device [
                          PositionSensor {
                            name "FL_rotula_chica_shoulder_joint_sensor"
                          }
                        ]
                        endPoint SolidReference {
                          solidName "FL_shoulder_link"
                        }
                      }
                    ]
                    name "FL_rotula_chica_servo_link"
                    physics Physics {
                      density -1
                      mass 0.021241
                      centerOfMass [
                        0.011945 0.016352 0
                      ]
                      inertiaMatrix [
                        1.378944e-06 9.354773e-07 2.188758e-06
                        -6.945552e-07 1.494924e-21 1.456809e-21
                      ]
                    }
                  }
                }
              ]
              name "FL_servo_tibia_link"
              physics Physics {
                density -1
                mass 0.009541
                centerOfMass [
                  -0.015986 0.004808 0.010758
                ]
                inertiaMatrix [
                  1.846483e-07 4.615207e-07 4.800254e-07
                  8.78258e-08 6.295155e-09 -1.913737e-09
                ]
              }
            }
          }
          HingeJoint {
            jointParameters HingeJointParameters {
              anchor 0.02675 0.010265 0.02005
            }
            device [
              PositionSensor {
                name "FL_shoulder_joint_sensor"
              }
            ]
            endPoint Solid {
              translation 0.02675 0.010265 0.02005
              rotation 0 1 0 1.570796
              children [
                Shape {
                  appearance DEF FL_shoulder_link_material PBRAppearance {
                    baseColor 0.752941 0 0
                    roughness 1
                    metalness 0
                  }
                  geometry DEF FL_shoulder_link Mesh {
                    url [
                      "../protos/URDF_MOSAC_V3/meshes/FL_shoulder_link.STL"
                    ]
                  }
                }
              ]
              name "FL_shoulder_link"
              physics Physics {
                density -1
                mass 0.014504
                centerOfMass [
                  0.000632 0.016182 0.013183
                ]
                inertiaMatrix [
                  9.29712e-07 8.99469e-07 1.560218e-06
                  -3.622225e-08 -4.929724e-09 2.805351e-08
                ]
              }
            }
          }
        ]
        name "BFL_link"
        physics Physics {
          density -1
          mass 0.146947
          centerOfMass [
            0.005804 -2e-06 0.030919
          ]
          inertiaMatrix [
            2.307477e-05 2.031684e-05 8.628932e-06
            -2.913178e-09 1.151036e-09 -3.558226e-10
          ]
        }
      }
    }
    HingeJoint {
      jointParameters HingeJointParameters {
        anchor -0.095 0.05275 0.0032
        dampingConstant 0.673885
      }
      device [
        RotationalMotor {
          name "BBL_joint"
          maxTorque 5.7
        }
        PositionSensor {
          name "BBL_joint_sensor"
        }
      ]
      endPoint Solid {
        translation -0.095 0.05275 0.0032
        rotation 0.5773502691896257 0.5773502691896257 0.5773502691896257 2.094395
        children [
          Shape {
            appearance DEF BBL_link_material PBRAppearance {
              roughness 1
              metalness 0
            }
            geometry DEF BBL_link Mesh {
              url [
                "../protos/URDF_MOSAC_V3/meshes/BBL_link.STL"
              ]
            }
          }
          HingeJoint {
            jointParameters HingeJointParameters {
              axis -1 0 0
              anchor 0.02675 0.010265 -0.04005
              dampingConstant 0.673885
            }
            device [
              RotationalMotor {
                name "BL_servo_femur_joint"
                maxTorque 5.7
              }
              PositionSensor {
                name "BL_servo_femur_joint_sensor"
              }
            ]
            endPoint Solid {
              translation 0.02675 0.010265 -0.04005
              rotation 0 1 0 1.570796
              children [
                Shape {
                  appearance DEF BL_servo_femur_link_material PBRAppearance {
                    roughness 1
                    metalness 0
                  }
                  geometry DEF BL_servo_femur_link Mesh {
                    url [
                      "../protos/URDF_MOSAC_V3/meshes/BL_servo_femur_link.STL"
                    ]
                  }
                }
                HingeJoint {
                  jointParameters HingeJointParameters {
                    axis 0 0 1
                    anchor 0.07355 -0.067752 0.02225
                  }
                  device [
                    PositionSensor {
                      name "BL_tibia_joint_sensor"
                    }
                  ]
                  endPoint Solid {
                    translation 0.07355 -0.067752 0.02225
                    children [
                      Shape {
                        appearance DEF BL_tibia_link_material PBRAppearance {
                          roughness 1
                          metalness 0
                        }
                        geometry DEF BL_tibia_link Mesh {
                          url [
                            "../protos/URDF_MOSAC_V3/meshes/BL_tibia_link.STL"
                          ]
                        }
                      }
                      HingeJoint {
                        jointParameters HingeJointParameters {
                          axis 0 0 -1
                          anchor 0.019092 0.019092 -0.00425
                        }
                        device [
                          PositionSensor {
                            name "BL_rotula_grande_tibia_joint_sensor"
                          }
                        ]
                        endPoint Solid {
                          translation 0.019092 0.019092 -0.00425
                          rotation 0 0 -1 0
                          children [
                            Shape {
                              appearance DEF BL_rotula_grande_tibia_link_material PBRAppearance {
                                baseColor 0.792157 0.603922 0.227451
                                roughness 1
                                metalness 0
                              }
                              geometry DEF BL_rotula_grande_tibia_link Mesh {
                                url [
                                  "../protos/URDF_MOSAC_V3/meshes/BL_rotula_grande_tibia_link.STL"
                                ]
                              }
                            }
                            HingeJoint {
                              jointParameters HingeJointParameters {
                                axis 0 0 -1
                                anchor -0.07355 0.067752 0
                              }
                              device [
                                PositionSensor {
                                  name "BL_rotula_grande_shoulder_joint_sensor"
                                }
                              ]
                              endPoint SolidReference {
                                solidName "BL_shoulder_link"
                              }
                            }
                          ]
                          name "BL_rotula_grande_tibia_link"
                          physics Physics {
                            density -1
                            mass 0.025031
                            centerOfMass [
                              -0.036775 0.033876 0
                            ]
                            inertiaMatrix [
                              2.194795e-06 2.50031e-06 4.514487e-06
                              1.858208e-06 9.045363e-22 -6.96262e-22
                            ]
                          }
                        }
                      }
                    ]
                    name "BL_tibia_link"
                    boundingObject Pose {
                      translation -0.074 -0.065 0
                      children [
                        Cylinder {
                          height 0.02
                          radius 0.02
                        }
                      ]
                    }
                    physics Physics {
                      density -1
                      mass 0.028632
                      centerOfMass [
                        -0.033067 -0.033197 -0.000996
                      ]
                      inertiaMatrix [
                        1.1409e-05 1.809981e-05 2.86846e-05
                        -1.319703e-05 2.026317e-07 2.003751e-07
                      ]
                    }
                  }
                }
              ]
              name "BL_servo_femur_link"
              physics Physics {
                density -1
                mass 0.032489
                centerOfMass [
                  0.026132 -0.02407 0.017002
                ]
                inertiaMatrix [
                  9.109723e-06 1.04594e-05 1.828839e-05
                  8.209302e-06 -4.435056e-07 4.08107e-07
                ]
              }
            }
          }
          HingeJoint {
            jointParameters HingeJointParameters {
              axis -1 0 0
              anchor 0.02375 -0.010265 -0.02005
              dampingConstant 0.673885
            }
            device [
              RotationalMotor {
                name "BL_servo_tibia_joint"
                maxTorque 5.7
              }
              PositionSensor {
                name "BL_servo_tibia_joint_sensor"
              }
            ]
            endPoint Solid {
              translation 0.02375 -0.010265 -0.02005
              rotation 0 1 0 1.570796
              children [
                Shape {
                  appearance DEF BL_servo_tibia_link_material PBRAppearance {
                    baseColor 0.898039 0.917647 0.929412
                    roughness 1
                    metalness 0
                  }
                  geometry DEF BL_servo_tibia_link Mesh {
                    url [
                      "../protos/URDF_MOSAC_V3/meshes/BL_servo_tibia_link.STL"
                    ]
                  }
                }
                HingeJoint {
                  jointParameters HingeJointParameters {
                    axis 0 0 1
                    anchor -0.022981 0.006918 0.0175
                  }
                  device [
                    PositionSensor {
                      name "BL_rotula_chica_servo_joint_sensor"
                    }
                  ]
                  endPoint Solid {
                    translation -0.022981 0.006918 0.0175
                    children [
                      Shape {
                        appearance DEF BL_rotula_chica_servo_link_material PBRAppearance {
                          baseColor 0.792157 0.603922 0.227451
                          roughness 1
                          metalness 0
                        }
                        geometry DEF BL_rotula_chica_servo_link Mesh {
                          url [
                            "../protos/URDF_MOSAC_V3/meshes/BL_rotula_chica_servo_link.STL"
                          ]
                        }
                      }
                      HingeJoint {
                        jointParameters HingeJointParameters {
                          axis 0 0 1
                          anchor 0.023889 0.032704 0
                        }
                        device [
                          PositionSensor {
                            name "BL_rotula_chica_shoulder_joint_sensor"
                          }
                        ]
                        endPoint SolidReference {
                          solidName "BL_shoulder_link"
                        }
                      }
                    ]
                    name "BL_rotula_chica_servo_link"
                    physics Physics {
                      density -1
                      mass 0.021241
                      centerOfMass [
                        0.011945 0.016352 0
                      ]
                      inertiaMatrix [
                        1.378944e-06 9.354773e-07 2.188758e-06
                        -6.945552e-07 -5.270875e-22 -3.803974e-22
                      ]
                    }
                  }
                }
              ]
              name "BL_servo_tibia_link"
              physics Physics {
                density -1
                mass 0.009541
                centerOfMass [
                  -0.015986 0.004808 0.010758
                ]
                inertiaMatrix [
                  1.846483e-07 4.615207e-07 4.800254e-07
                  8.78258e-08 6.295155e-09 -1.913737e-09
                ]
              }
            }
          }
          HingeJoint {
            jointParameters HingeJointParameters {
              anchor 0.02675 0.010265 -0.04005
            }
            device [
              PositionSensor {
                name "BL_shoulder_joint_sensor"
              }
            ]
            endPoint Solid {
              translation 0.02675 0.010265 -0.04005
              rotation 0 1 0 1.570796
              children [
                Shape {
                  appearance DEF BL_shoulder_link_material PBRAppearance {
                    baseColor 0.752941 0 0
                    roughness 1
                    metalness 0
                  }
                  geometry DEF BL_shoulder_link Mesh {
                    url [
                      "../protos/URDF_MOSAC_V3/meshes/BL_shoulder_link.STL"
                    ]
                  }
                }
              ]
              name "BL_shoulder_link"
              physics Physics {
                density -1
                mass 0.014229
                centerOfMass [
                  0.000274 0.016126 0.01335
                ]
                inertiaMatrix [
                  9.001932e-07 8.699501e-07 1.559908e-06
                  -3.622225e-08 -4.929724e-09 2.805351e-08
                ]
              }
            }
          }
        ]
        name "BBL_link"
        physics Physics {
          density -1
          mass 0.146947
          centerOfMass [
            0.005804 2e-06 -0.030919
          ]
          inertiaMatrix [
            2.307477e-05 2.031684e-05 8.628932e-06
            2.913178e-09 -1.151036e-09 -3.558226e-10
          ]
        }
      }
    }
  ]
  name "URDFMOSACV3"
  boundingObject Box {
    size 0.36 0.135 0.085
  }
  physics Physics {
    density -1
    mass 1.295533
    centerOfMass [
      0.000198 0.00079 -0.002561
    ]
    inertiaMatrix [
      0.0008332027 0.001685128 0.001899702
      1.968757e-06 1.644814e-06 -6.887399e-07
    ]
  }
  controller "MOSAC_Controller"
  supervisor TRUE
}
Floor {
}
